Workbook

Sheet Project Budget
A1: No. | B1: Item | C1: Details | D1: Cost type | E1: Qty | F1: Unit | G1: Rate (Rs.) | H1: Duration / hours | I1: Total (Rs.)
B2: Personnel
A3: 1 | B3: Project management and documentation (Laiba) | C3: SPMP, reports, supervisor meetings | D3: In-kind | E3: 1 | F3: hours | G3: 450 | H3: 90 | I3: =E3*G3*H3 -> 40500
A4: 2 | B4: Requirements, UI mockups and SRS (Laiba) | C4: User classes, mockups M1 to M10, SRS | D4: In-kind | E4: 1 | F4: hours | G4: =Assumptions!$B$13 -> 450 | H4: 90 | I4: =E4*G4*H4 -> 40500
A5: 3 | B5: Frontend development, Flutter app (Laiba) | C5: Desktop app screens and integration | D5: In-kind | E5: 1 | F5: hours | G5: =Assumptions!$B$11 -> 450 | H5: 190 | I5: =E5*G5*H5 -> 85500
A6: 4 | B6: System design (Waris) | C6: Architecture, UML, database design | D6: In-kind | E6: 1 | F6: hours | G6: =Assumptions!$B$12 -> 600 | H6: 50 | I6: =E6*G6*H6 -> 30000
A7: 5 | B7: Dataset collection and labelling (Waris) | C7: AI-generated Express apps and CWE labels | D7: In-kind | E7: 1 | F7: hours | G7: =Assumptions!$B$12 -> 600 | H7: 90 | I7: =E7*G7*H7 -> 54000
A8: 6 | B8: Model fine-tuning and evaluation (Waris) | C8: CodeBERT / GraphCodeBERT, calibration | D8: In-kind | E8: 1 | F8: hours | G8: =Assumptions!$B$12 -> 600 | H8: 90 | I8: =E8*G8*H8 -> 54000
A9: 7 | B9: Scan engine, fixes and export (Waris) | C9: Parser, route analyzer, rules, fixes, PDF and SARIF | D9: In-kind | E9: 1 | F9: hours | G9: =Assumptions!$B$12 -> 600 | H9: 140 | I9: =E9*G9*H9 -> 84000
A10: 8 | B10: Supervisor guidance | C10: Provided by the university, not charged | D10: In-kind | E10: 1 | F10: hours | G10: 0 | H10: 0 | I10: =E10*G10*H10 -> 0
B11: Subtotal - Personnel | I11: =SUM(I3:I10) -> 388500
B13: Software and Development Tools
A14: 9 | B14: Flutter, Dart, VS Code, Visual Studio Community | C14: Desktop app development | D14: Free | E14: 1 | F14: set | G14: 0 | H14: 1 | I14: =E14*G14*H14 -> 0
A15: 10 | B15: Python, PyTorch, Hugging Face Transformers | C15: Model training and running on CPU | D15: Free | E15: 1 | F15: set | G15: 0 | H15: 1 | I15: =E15*G15*H15 -> 0
A16: 11 | B16: Tree-sitter, SQLite, Node.js, Express | C16: Parsing, local database, sample apps | D16: Free | E16: 1 | F16: set | G16: 0 | H16: 1 | I16: =E16*G16*H16 -> 0
A17: 12 | B17: Git, GitHub, ClickUp, draw.io, Google Docs | C17: Version control, planning, diagrams, documents | D17: Free | E17: 1 | F17: set | G17: 0 | H17: 1 | I17: =E17*G17*H17 -> 0
A18: 13 | B18: Semgrep, Gitleaks, PyInstaller, Inno Setup | C18: Baseline tools for evaluation, installer | D18: Free | E18: 1 | F18: set | G18: 0 | H18: 1 | I18: =E18*G18*H18 -> 0
B19: Subtotal - Software and Development Tools | I19: =SUM(I14:I18) -> 0
B21: Hardware and Infrastructure
A22: 14 | B22: Developer laptops (owned) | C22: Depreciation = value / useful life per month | D22: In-kind | E22: =Assumptions!$B$7 -> 2 | F22: laptops | G22: =Assumptions!$B$15/Assumptions!$B$16 -> 2708.3333 | H22: =Assumptions!$B$6 -> 7 | I22: =E22*G22*H22 -> 37916.667
A23: 15 | B23: Home internet | C23: Already paid by each student | D23: In-kind | E23: =Assumptions!$B$7 -> 2 | F23: students | G23: =Assumptions!$B$17 -> 3500 | H23: =Assumptions!$B$6 -> 7 | I23: =E23*G23*H23 -> 49000
A24: 16 | B24: External backup drive, 1 TB | C24: Backup of dataset, model files, documents | D24: Cash | E24: 1 | F24: drive | G24: =Assumptions!$B$18 -> 14000 | H24: 1 | I24: =E24*G24*H24 -> 14000
B25: Subtotal - Hardware and Infrastructure | I25: =SUM(I22:I24) -> 100916.67
B27: Cloud Computing and Model Training
A28: 17 | B28: Google Colab and Kaggle free GPU | C28: Model fine-tuning on free tier | D28: Free | E28: 1 | F28: service | G28: 0 | H28: 1 | I28: =E28*G28*H28 -> 0
A29: 18 | B29: Google Colab Pro, 2 months | C29: In case the free GPU limit is not enough | D29: Cash | E29: 1 | F29: subscription | G29: =Assumptions!$B$19*Assumptions!$B$9 -> 2800 | H29: 2 | I29: =E29*G29*H29 -> 5600
A30: 19 | B30: Google Drive free storage | C30: Checkpoints and backups | D30: Free | E30: 1 | F30: service | G30: 0 | H30: 1 | I30: =E30*G30*H30 -> 0
A31: 20 | B31: Cloud hosting for the product | C31: Not needed: LYKOS runs on the user's computer | D31: Free | E31: 0 | F31: service | G31: 0 | H31: 1 | I31: =E31*G31*H31 -> 0
B32: Subtotal - Cloud Computing and Model Training | I32: =SUM(I28:I31) -> 5600
B34: Testing and Quality Assurance
A35: 21 | B35: Testing effort (Laiba) | C35: Test plan, test cases, usability test | D35: In-kind | E35: 1 | F35: hours | G35: =Assumptions!$B$14 -> 400 | H35: 50 | I35: =E35*G35*H35 -> 20000
A36: 22 | B36: Testing effort (Waris) | C36: Unit, integration and performance tests | D36: In-kind | E36: 1 | F36: hours | G36: =Assumptions!$B$14 -> 400 | H36: 50 | I36: =E36*G36*H36 -> 20000
A37: 23 | B37: pytest, flutter_test, SonarQube Community, Ruff | C37: Test frameworks and code analysis | D37: Free | E37: 1 | F37: set | G37: 0 | H37: 1 | I37: =E37*G37*H37 -> 0
A38: 24 | B38: Usability test refreshments | C38: 5 volunteer testers | D38: Cash | E38: 5 | F38: persons | G38: =Assumptions!$B$20 -> 500 | H38: 1 | I38: =E38*G38*H38 -> 2500
B39: Subtotal - Testing and Quality Assurance | I39: =SUM(I35:I38) -> 42500
B41: Documentation, Printing and Travel
A42: 25 | B42: Final report printing and binding | C42: 4 copies | D42: Cash | E42: 4 | F42: copies | G42: =Assumptions!$B$21 -> 1500 | H42: 1 | I42: =E42*G42*H42 -> 6000
A43: 26 | B43: Poster printing | C43: Final presentation | D43: Cash | E43: 1 | F43: poster | G43: =Assumptions!$B$22 -> 2000 | H43: 1 | I43: =E43*G43*H43 -> 2000
A44: 27 | B44: Travel to university | C44: Supervisor meetings and demos, one trip every 2 weeks per student | D44: Cash | E44: =Assumptions!$B$7 -> 2 | F44: students | G44: =Assumptions!$B$23 -> 400 | H44: =ROUNDDOWN(Assumptions!$B$5/2,0) -> 14 | I44: =E44*G44*H44 -> 11200
B45: Subtotal - Documentation, Printing and Travel | I45: =SUM(I42:I44) -> 19200
...

Sheet Cost Summary
A1: Cost category | B1: Total (Rs.) | C1: Cash (Rs.) | D1: In-kind (Rs.) | E1: Share of total
A2: Personnel | B2: ='Project Budget'!$I$11 -> 388500 | C2: =SUMIF('Project Budget'!$D$3:$D$10,"Cash",'Project Budget'!$I$3:$I$10) -> 0 | D2: =SUMIF('Project Budget'!$D$3:$D$10,"In-kind",'Project Budget'!$I$3:$I$10) -> 388500 | E2: =IF($B$8=0,0,B2/$B$8) -> 0.69784151
A3: Software and Development Tools | B3: ='Project Budget'!$I$19 -> 0 | C3: =SUMIF('Project Budget'!$D$14:$D$18,"Cash",'Project Budget'!$I$14:$I$18) -> 0 | D3: =SUMIF('Project Budget'!$D$14:$D$18,"In-kind",'Project Budget'!$I$14:$I$18) -> 0 | E3: =IF($B$8=0,0,B3/$B$8) -> 0
A4: Hardware and Infrastructure | B4: ='Project Budget'!$I$25 -> 100916.67 | C4: =SUMIF('Project Budget'!$D$22:$D$24,"Cash",'Project Budget'!$I$22:$I$24) -> 14000 | D4: =SUMIF('Project Budget'!$D$22:$D$24,"In-kind",'Project Budget'!$I$22:$I$24) -> 86916.667 | E4: =IF($B$8=0,0,B4/$B$8) -> 0.18127114
A5: Cloud Computing and Model Training | B5: ='Project Budget'!$I$32 -> 5600 | C5: =SUMIF('Project Budget'!$D$28:$D$31,"Cash",'Project Budget'!$I$28:$I$31) -> 5600 | D5: =SUMIF('Project Budget'!$D$28:$D$31,"In-kind",'Project Budget'!$I$28:$I$31) -> 0 | E5: =IF($B$8=0,0,B5/$B$8) -> 0.010058977
A6: Testing and Quality Assurance | B6: ='Project Budget'!$I$39 -> 42500 | C6: =SUMIF('Project Budget'!$D$35:$D$38,"Cash",'Project Budget'!$I$35:$I$38) -> 2500 | D6: =SUMIF('Project Budget'!$D$35:$D$38,"In-kind",'Project Budget'!$I$35:$I$38) -> 40000 | E6: =IF($B$8=0,0,B6/$B$8) -> 0.076340448
A7: Documentation, Printing and Travel | B7: ='Project Budget'!$I$45 -> 19200 | C7: =SUMIF('Project Budget'!$D$42:$D$44,"Cash",'Project Budget'!$I$42:$I$44) -> 19200 | D7: =SUMIF('Project Budget'!$D$42:$D$44,"In-kind",'Project Budget'!$I$42:$I$44) -> 0 | E7: =IF($B$8=0,0,B7/$B$8) -> 0.03448792
A8: Project subtotal | B8: =SUM(B2:B7) -> 556716.67 | C8: =SUM(C2:C7) -> 41300 | D8: =SUM(D2:D7) -> 515416.67 | E8: =SUM(E2:E7) -> 1
A9: Contingency | B9: =B8*Assumptions!$B$10 -> 55671.667 | C9: =C8*Assumptions!$B$10 -> 4130 | D9: =D8*Assumptions!$B$10 -> 51541.667 | E9: =Assumptions!$B$10 -> 0.1
A10: Final project budget (with contingency) | B10: =B8+B9 -> 612388.33 | C10: =C8+C9 -> 45430 | D10: =D8+D9 -> 566958.33
A12: Cash needed per student (with contingency) | B12: =C10/Assumptions!$B$7 -> 22715
A13: Budget per working day | B13: =B10/Assumptions!$B$4 -> 4469.9878
A14: Planned student hours | B14: =SUMPRODUCT(('Project Budget'!$F$3:$F$57="hours")*'Project Budget'!$E$3:$E$57*'Project Budget'!$H$3:$H$57) -> 840
A15: Available student hours | B15: =Assumptions!$B$7*Assumptions!$B$8*Assumptions!$B$5 -> 840

Sheet Assumptions
A1: Assumption | B1: Value | C1: Note
A2: Project start date | B2: 46328 | C2: As per the project schedule
A3: Project end date | B3: 46518 | C3: Final delivery milestone
A4: Working days (Mon to Fri) | B4: =NETWORKDAYS(B2,B3) -> 137 | C4: Public holidays not removed
A5: Working weeks | B5: =ROUNDUP(B4/5,0) -> 28 | C5: Working days / 5
A6: Months (rounded up) | B6: =ROUNDUP((B3-B2)/30.4375,0) -> 7 | C6: Used for depreciation and internet
A7: Team members | B7: 2 | C7: Laiba and Waris
A8: Hours per student per week | B8: 15 | C8: Effort alongside other courses
A9: Exchange rate (Rs. per USD) | B9: 280 | C9: Approximate; used for USD prices
A10: Contingency (% of subtotal) | B10: 0.1 | C10: For unexpected costs and estimation errors
A11: Hourly rate: Flutter / frontend developer | B11: 450 | C11: Approximate junior rate in Pakistan
A12: Hourly rate: backend / ML engineer | B12: 600 | C12: Approximate junior rate in Pakistan
A13: Hourly rate: project manager / analyst | B13: 450 | C13: Approximate junior rate
A14: Hourly rate: tester / QA | B14: 400 | C14: Approximate junior rate
A15: Laptop value (each) | B15: 130000 | C15: Both laptops are already owned
A16: Laptop useful life (months) | B16: 48 | C16: Straight-line depreciation
A17: Internet per student per month | B17: 3500 | C17: Already paid by each student
A18: External backup drive, 1 TB | B18: 14000 | C18: Shop price estimate
... A23: Travel to university per trip | B23: 400 | C23: Local transport, one student, one way plus return
